<sdf version='1.7'>
  <model name='jebi'>
    <link name='body'>
      <inertial>
        <pose>0 0.082241 0 0 -0 0</pose>
        <mass>1.5</mass>
        <inertia>
          <ixx>0.21515</ixx>
          <ixy>-1.0545e-07</ixy>
          <ixz>-5.8048e-07</ixz>
          <iyy>0.1799</iyy>
          <iyz>1.4892e-07</iyz>
          <izz>0.038544</izz>
        </inertia>
      </inertial>
      <collision name='body_collision'>
        <pose>0 0 0 0 -0 0</pose>
        <geometry>
          <mesh>
            <scale>1 1 1</scale>
            <uri>model://jebi/meshes/body.STL</uri>
          </mesh>
        </geometry>
      </collision>
      <visual name='body_visual'>
        <pose>0 0 0 0 -0 0</pose>
        <geometry>
          <mesh>
            <scale>1 1 1</scale>
            <uri>model://jebi/meshes/body.STL</uri>
          </mesh>
        </geometry>
      </visual>
    </link>
    <joint name='elevon1' type='revolute'>
      <pose relative_to='body'>0 0.16162 0.09976 -1.5708 -0 -1.5708</pose>
      <parent>body</parent>
      <child>link3</child>
      <axis>
        <xyz>0 1 0</xyz>
        <limit>
          <lower>-1.5708</lower>
          <upper>1.5708</upper>
          <effort>0</effort>
          <velocity>0</velocity>
        </limit>
        <dynamics>
          <spring_reference>0</spring_reference>
          <spring_stiffness>0</spring_stiffness>
        </dynamics>
      </axis>
    </joint>
    <link name='link3'>
      <pose relative_to='elevon1'>0 0 0 0 -0 0</pose>
      <inertial>
        <pose>-0.025228 -0.13979 0 0 -0 0</pose>
        <mass>0.05</mass>
        <inertia>
          <ixx>0.0016447</ixx>
          <ixy>1.4302e-06</ixy>
          <ixz>5.1488e-11</ixz>
          <iyy>0.00013377</iyy>
          <iyz>5.2895e-10</iyz>
          <izz>0.0017717</izz>
        </inertia>
      </inertial>
      <collision name='link3_collision'>
        <pose>0 0 0 0 -0 0</pose>
        <geometry>
          <mesh>
            <scale>1 1 1</scale>
            <uri>model://jebi/meshes/link3.STL</uri>
          </mesh>
        </geometry>
      </collision>
      <visual name='link3_visual'>
        <pose>0 0 0 0 -0 0</pose>
        <geometry>
          <mesh>
            <scale>1 1 1</scale>
            <uri>model://jebi/meshes/link3.STL</uri>
          </mesh>
        </geometry>
      </visual>
    </link>
    <joint name='elevon2' type='revolute'>
      <pose relative_to='body'>0 0.16162 -0.09976 -1.5708 -0 -1.5708</pose>
      <parent>body</parent>
      <child>link4</child>
      <axis>
        <xyz>0 1 0</xyz>
        <limit>
          <lower>-1.5708</lower>
          <upper>1.5708</upper>
          <effort>0</effort>
          <velocity>0</velocity>
        </limit>
        <dynamics>
          <spring_reference>0</spring_reference>
          <spring_stiffness>0</spring_stiffness>
        </dynamics>
      </axis>
    </joint>
    <link name='link4'>
      <pose relative_to='elevon2'>0 0 0 0 -0 0</pose>
      <inertial>
        <pose>-0.025228 0.1398 -0 0 -0 0</pose>
        <mass>0.05</mass>
        <inertia>
          <ixx>0.0016448</ixx>
          <ixy>-1.3458e-06</ixy>
          <ixz>3.0559e-10</ixz>
          <iyy>0.00013376</iyy>
          <iyz>-7.1007e-11</iyz>
          <izz>0.0017717</izz>
        </inertia>
      </inertial>
      <collision name='link4_collision'>
        <pose>0 0 0 0 -0 0</pose>
        <geometry>
          <mesh>
            <scale>1 1 1</scale>
            <uri>model://jebi/meshes/link4.STL</uri>
          </mesh>
        </geometry>
      </collision>
      <visual name='link4_visual'>
        <pose>0 0 0 0 -0 0</pose>
        <geometry>
          <mesh>
            <scale>1 1 1</scale>
            <uri>model://jebi/meshes/link4.STL</uri>
          </mesh>
        </geometry>
      </visual>
    </link>
    <joint name='prop1' type='revolute'>
      <pose relative_to='body'>0 -0.073312 0.23 0 0.84505 -3.14159</pose>
      <parent>body</parent>
      <child>link1</child>
      <axis>
        <xyz>0 0 1</xyz>
        <limit>
          <lower>-3.14</lower>
          <upper>3.14</upper>
          <effort>0</effort>
          <velocity>0</velocity>
        </limit>
        <dynamics>
          <spring_reference>0</spring_reference>
          <spring_stiffness>0</spring_stiffness>
        </dynamics>
      </axis>
    </joint>
    <link name='link1'>
      <pose relative_to='prop1'>0 0 0 0 -0 0</pose>
      <inertial>
        <pose>-1e-06 0.008409 0 0 -0 0</pose>
        <mass>0.01</mass>
        <inertia>
          <ixx>7.9824e-07</ixx>
          <ixy>1.6586e-10</ixy>
          <ixz>2.5599e-06</ixz>
          <iyy>6.5806e-05</iyy>
          <iyz>-5.3779e-11</iyz>
          <izz>6.5331e-05</izz>
        </inertia>
      </inertial>
      <collision name='link1_collision'>
        <pose>0 0 0 0 -0 0</pose>
        <geometry>
          <mesh>
            <scale>1 1 1</scale>
            <uri>model://jebi/meshes/link1.STL</uri>
          </mesh>
        </geometry>
      </collision>
      <visual name='link1_visual'>
        <pose>0 0 0 0 -0 0</pose>
        <geometry>
          <mesh>
            <scale>1 1 1</scale>
            <uri>model://jebi/meshes/link1.STL</uri>
          </mesh>
        </geometry>
      </visual>
    </link>
    <joint name='prop2' type='revolute'>
      <pose relative_to='body'>0 -0.073312 -0.23 3.14159 0.73601 3.14159</pose>
      <parent>body</parent>
      <child>link2</child>
      <axis>
        <xyz>0 0 1</xyz>
        <limit>
          <lower>-3.14</lower>
          <upper>3.14</upper>
          <effort>0</effort>
          <velocity>0</velocity>
        </limit>
        <dynamics>
          <spring_reference>0</spring_reference>
          <spring_stiffness>0</spring_stiffness>
        </dynamics>
      </axis>
    </joint>
    <link name='link2'>
      <pose relative_to='prop2'>0 0 0 0 -0 0</pose>
      <inertial>
        <pose>-3e-06 -0.008409 0 0 -0 0</pose>
        <mass>0.01</mass>
        <inertia>
          <ixx>7.9814e-07</ixx>
          <ixy>-1.1708e-10</ixy>
          <ixz>2.5593e-06</ixz>
          <iyy>6.5791e-05</iyy>
          <iyz>5.3166e-11</iyz>
          <izz>6.5317e-05</izz>
        </inertia>
      </inertial>
      <collision name='link2_collision'>
        <pose>0 0 0 0 -0 0</pose>
        <geometry>
          <mesh>
            <scale>1 1 1</scale>
            <uri>model://jebi/meshes/link2.STL</uri>
          </mesh>
        </geometry>
      </collision>
      <visual name='link2_visual'>
        <pose>0 0 0 0 -0 0</pose>
        <geometry>
          <mesh>
            <scale>1 1 1</scale>
            <uri>model://jebi/meshes/link2.STL</uri>
          </mesh>
        </geometry>
      </visual>
    </link>
  </model>
</sdf>
